Workbook

Sheet Form Responses 1
A1: Timestamp | B1: First name | C1: Last name | D1: Pitt email address | E1: Top choices [CS 0007] | F1: Top choices [CS 0011/0012] | G1: Top choices [CMPINF 0401] | H1: Top choices [CS 0441] | I1: Top choices [CS 0445] | J1: Top choices [CS 0447] | K1: Top choices [CS 0449] | L1: Top choices [CS 0590] | M1: Top choices [CS 1501] | N1: Top choices [CS 1502] | O1: Top choices [CS 1503] | P1: Top choices [CS 1510/2012] | Q1: Top choices [CS 1520] | R1: Top choices [CS 1530] | S1: Top choices [CS 1550] | T1: Top choices [CS 1555/2055] | U1: Top choices [CS 1566] | V1: Top choices [CS 1571] | W1: Top choices [CS 1632] | X1: Top choices [CS 1635/2035] | Y1: Top choices [CS 1980/1640] | Z1: Top choices [CS 1656] | AA1: Top choices [CS 1660/2060] | AB1: Top choices [CS 1666] | AC1: Top choices [CS 1671/2071] | AD1: Top choices [CS 1674/2074] | AE1: Top choices [CS 1675/2075] | AF1: Top choices [CS 1684/2084] | AG1: Top choices [CS 1699] | AH1: Top choices [CS 1900/1950] | AI1: Top choices [CS 2210] | AJ1: Top choices [CS 2520] | AK1: Top choices [CS 2710] | AL1: Top choices [CS 2731] | AM1: Top choices [CS 2750] | AN1: Top choices [CS 2893] | AO1: Topic Areas [Introductory programming (could be Python or Java)] | AP1: Topic Areas [Core programming in Java] | AQ1: Topic Areas [Computer systems/architecture] | AR1: Topic Areas [Theory and mathematical foundations] | AS1: Topic Areas [Programming practice and software engineering] | AT1: Topic Areas [Artificial intelligence and machine learning] | AU1: Topic Areas [Security and networks] | AV1: Topic Areas [Data management and organization] | AW1: Scheduling constraints | AX1: Courses constraints | AY1: Goals | AZ1: Anything else we should know? For example: courses that you wish to avoid (explain!), etc.
A2: 46246.533 | B2: A | C2: Y | D2: a@pitt.edu | E2: Third Choice Group | F2: Third Choice Group | G2: Third Choice Group | H2: Third Choice Group | I2: Third Choice Group | J2: Third Choice Group | K2: Third Choice Group | L2: Third Choice Group | M2: Third Choice Group | N2: Third Choice Group | O2: Third Choice Group | P2: Third Choice Group | Q2: Third Choice Group | R2: Third Choice Group | S2: Third Choice Group | T2: Third Choice Group | U2: Third Choice Group | V2: Third Choice Group | W2: Third Choice Group | X2: First Choice Group | Y2: Third Choice Group | Z2: First Choice Group | AA2: Third Choice Group | AB2: Third Choice Group | AC2: First Choice Group | AD2: First Choice Group | AE2: First Choice Group | AF2: First Choice Group | AG2: Second Choice | AH2: Third Choice Group | AI2: Third Choice Group | AJ2: Third Choice Group | AK2: First Choice Group | AL2: First Choice Group | AM2: First Choice Group | AN2: Third Choice Group | AO2: Excellent | AP2: Excellent | AQ2: Unsatisfactory | AR2: Unsatisfactory | AS2: Strong | AT2: Excellent | AU2: Satisfactory | AV2: Strong | AW2: Friday 12-4PM | AX2: N/A | AY2: Funding, Teaching experience | AZ2: CS1503 or 1555 since I find it hard to work with Dr Marina Barsky - great person, but hard to work with because it’s very hard to convince her on any changes on course structure
A3: 46246.557 | B3: B | C3: Z | D3: b@pitt.edu | E3: First Choice Group | F3: First Choice Group | G3: First Choice Group | H3: First Choice Group | I3: First Choice Group | J3: Third Choice Group | K3: First Choice Group | L3: Third Choice Group | M3: First Choice Group | N3: Third Choice Group | O3: Third Choice Group | P3: First Choice Group | Q3: First Choice Group | R3: Third Choice Group | S3: First Choice Group | T3: First Choice Group | U3: Third Choice Group | V3: Third Choice Group | W3: Third Choice Group | X3: Third Choice Group | Y3: Third Choice Group | Z3: First Choice Group | AA3: Second Choice | AB3: Second Choice | AC3: Second Choice | AD3: Second Choice | AE3: Second Choice | AF3: Second Choice | AG3: Second Choice | AH3: Second Choice | AI3: Third Choice Group | AJ3: Second Choice | AK3: Second Choice | AL3: Second Choice | AM3: Second Choice | AN3: Third Choice Group | AO3: Strong | AP3: Strong | AQ3: Satisfactory | AR3: Unsatisfactory | AS3: Strong | AT3: Strong | AU3: Strong | AV3: Strong | AW3: Monday: 11:00 AM–12:15 PM; 6:00–8:30 PM Tuesday: 1:00–1:30 PM; 4:00–5:15 PM Wednesday: 11:00 AM–12:15 PM Thursday: 4:00–5:15 PM Friday: 1:00–1:30 PM | AX3: CS 2710: Foundations of Artificial Intelligence CS 2750: Machine Learning CS 2893: Modern Quantum Computing CS 2990: Independent Study | AY3: Funding, Learn a new topic | AZ3: Avoid theory topic; Not interested in teaching ; Thank you very much! ;)
A4: 46246.558 | B4: C | C4: A | D4: c@pitt.edu | E4: Third Choice Group | F4: Third Choice Group | G4: Third Choice Group | H4: Third Choice Group | I4: Second Choice | J4: Third Choice Group | K4: Third Choice Group | L4: Third Choice Group | M4: Third Choice Group | N4: Third Choice Group | O4: Third Choice Group | P4: Third Choice Group | Q4: Second Choice | R4: Third Choice Group | S4: Second Choice | T4: Third Choice Group | U4: Third Choice Group | V4: Third Choice Group | W4: Third Choice Group | X4: Third Choice Group | Y4: Third Choice Group | Z4: First Choice Group | AA4: Third Choice Group | AB4: Third Choice Group | AC4: Third Choice Group | AD4: Third Choice Group | AE4: Third Choice Group | AF4: Third Choice Group | AG4: Third Choice Group | AH4: Third Choice Group | AI4: Third Choice Group | AJ4: Third Choice Group | AK4: Third Choice Group | AL4: Third Choice Group | AM4: Third Choice Group | AN4: Third Choice Group | AO4: Excellent | AP4: Excellent | AQ4: Strong | AR4: Unsatisfactory | AS4: Excellent | AT4: Strong | AU4: Satisfactory | AV4: Excellent | AW4: No real constraints | AX4: No conflicts | AY4: Funding, Teaching experience | AZ4: If there are multiple sections of cs1656, I prefer to be assigned to the one of Dr. Labrinidis
A5: 46246.573 | B5: D | C5: B | D5: d@pitt.edu | E5: First Choice Group | F5: First Choice Group | G5: First Choice Group | H5: First Choice Group | I5: Cannot TA Group (explain below) | J5: Cannot TA Group (explain below) | K5: Cannot TA Group (explain below) | L5: First Choice Group | M5: Cannot TA Group (explain below) | N5: Cannot TA Group (explain below) | O5: First Choice Group | P5: Cannot TA Group (explain below) | Q5: First Choice Group | R5: First Choice Group | S5: Cannot TA Group (explain below) | T5: Cannot TA Group (explain below) | U5: Cannot TA Group (explain below) | V5: First Choice Group | W5: First Choice Group | X5: First Choice Group | Y5: First Choice Group | Z5: First Choice Group | AA5: First Choice Group | AB5: First Choice Group | AC5: First Choice Group | AD5: First Choice Group | AE5: First Choice Group | AF5: First Choice Group | AG5: First Choice Group | AH5: First Choice Group | AI5: Cannot TA Group (explain below) | AJ5: Cannot TA Group (explain below) | AK5: First Choice Group | AL5: First Choice Group | AM5: First Choice Group | AN5: Cannot TA Group (explain below) | AO5: Excellent | AP5: Excellent | AQ5: Unsatisfactory | AR5: Unsatisfactory | AS5: Unsatisfactory | AT5: Excellent | AU5: Unsatisfactory | AV5: Unsatisfactory | AW5: Not available Monday Tuesday Wednesday (all day); only available Thursday afternoon and Friday (all day) | AX5: Cannot do algorithms, systems or architecture courses; only can do introductory programing courses | AY5: Funding, Teaching experience, Improve public speaking or other skills | AZ5: definitely want to avoid - assembly language, architecture, formal methods, algorithms, systems courses; prefer intro programming, data science, hci or ai courses!
A6: 46246.574 | B6: E | C6: C | D6: e@pitt.edu | E6: Third Choice Group | F6: Third Choice Group | G6: Third Choice Group | H6: Third Choice Group | I6: Third Choice Group | J6: Third Choice Group | K6: Third Choice Group | L6: Third Choice Group | M6: Third Choice Group | N6: Third Choice Group | O6: Third Choice Group | P6: Third Choice Group | Q6: Third Choice Group | R6: Third Choice Group | S6: Third Choice Group | T6: Third Choice Group | U6: Third Choice Group | V6: Second Choice | W6: Third Choice Group | X6: Third Choice Group | Y6: Third Choice Group | Z6: Second Choice | AA6: Third Choice Group | AB6: Third Choice Group | AC6: Second Choice | AD6: Second Choice | AE6: Second Choice | AF6: Third Choice Group | AG6: Third Choice Group | AH6: Third Choice Group | AI6: Third Choice Group | AJ6: Cannot TA Group (explain below) | AK6: First Choice Group | AL6: Second Choice | AM6: First Choice Group | AN6: Cannot TA Group (explain below) | AO6: Satisfactory | AP6: Satisfactory | AQ6: Satisfactory | AR6: Satisfactory | AS6: Strong | AT6: Excellent | AU6: Unsatisfactory | AV6: Satisfactory | AW6: Potential conferences that I may have to make time for: NeurIPS (Dec 6-13). This can be limited to a few days depending if/when we have to present. | AX6: NA | AY6: Funding | AZ6: Only because of my limited understanding about these topics: MODERN QUANTUM COMPUTING, WIDE AREA NETWORKS.
A7: 46246.574 | B7: F | C7: D | D7: f@pitt.edu | E7: Third Choice Group | F7: Third Choice Group | G7: Third Choice Group | H7: Third Choice Group | I7: Third Choice Group | J7: Third Choice Group | K7: Third Choice Group | L7: Third Choice Group | M7: Third Choice Group | N7: Third Choice Group | O7: Third Choice Group | P7: Second Choice | Q7: Third Choice Group | R7: Third Choice Group | S7: Third Choice Group | T7: Third Choice Group | U7: Third Choice Group | V7: Second Choice | W7: Third Choice Group | X7: Third Choice Group | Y7: Third Choice Group | Z7: Second Choice | AA7: Third Choice Group | AB7: Third Choice Group | AC7: Third Choice Group | AD7: First Choice Group | AE7: Cannot TA Group (explain below) | AF7: Third Choice Group | AG7: Third Choice Group | AH7: Third Choice Group | AI7: Third Choice Group | AJ7: Third Choice Group | AK7: Third Choice Group | AL7: Third Choice Group | AM7: First Choice Group | AN7: Third Choice Group | AO7: Satisfactory | AP7: Satisfactory | AQ7: Satisfactory | AR7: Satisfactory | AS7: Satisfactory | AT7: Strong | AU7: Unsatisfactory | AV7: Satisfactory | AW7: Monday & Wednesday: 11:00 AM–12:15 PM (CS 2075), 2:00 PM–3:20 PM, 4:30 PM–5:45 PM (BIOST 2041) Thursday: 2:30 PM–3:45 PM (BIOST 2041 Recitation) Friday: 11:00 AM–11:50 AM (CS 2075 Recitation) | AX7: CS 2075 | AY7: Funding, Teaching experience, Improve public speaking or other skills, Learn a new topic | AZ7: no
A8: 46246.58 | B8: G | C8: E | D8: g@pitt.edu | E8: Third Choice Group | F8: Third Choice Group | G8: Third Choice Group | H8: Third Choice Group | I8: Third Choice Group | J8: Cannot TA Group (explain below) | K8: Cannot TA Group (explain below) | L8: Second Choice | M8: Third Choice Group | N8: Cannot TA Group (explain below) | O8: Third Choice Group | P8: Third Choice Group | Q8: Cannot TA Group (explain below) | R8: Third Choice Group | S8: Cannot TA Group (explain below) | T8: Third Choice Group | U8: Cannot TA Group (explain below) | V8: First Choice Group | W8: Third Choice Group | X8: Cannot TA Group (explain below) | Y8: Second Choice | Z8: Third Choice Group | AA8: Third Choice Group | AB8: Cannot TA Group (explain below) | AC8: First Choice Group | AD8: Third Choice Group | AE8: Second Choice | AF8: First Choice Group | AG8: Second Choice | AH8: Second Choice | AI8: Cannot TA Group (explain below) | AJ8: Second Choice | AK8: First Choice Group | AL8: First Choice Group | AM8: First Choice Group | AN8: Cannot TA Group (explain below) | AO8: Strong | AP8: Satisfactory | AQ8: Unsatisfactory | AR8: Unsatisfactory | AS8: Satisfactory | AT8: Excellent | AU8: Unsatisfactory | AV8: Satisfactory | AW8: NA | AX8: NA | AY8: Funding | AZ8: CS 0447/CS 0449/CS 1550 (computer systems/architecture), CS 1502/CS 2210/CS 2893 (theory/math foundations), CS 1520 (security/networks), and CS 1566/CS 1635/CS 1666 (interface/graphics): as a PhD student in ML/NLP/AI-related research, I don't have sufficient TA background in these areas outside my specialization
A9: 46246.598 | B9: H | C9: F | D9: h@pitt.edu | E9: Cannot TA Group (explain below) | F9: Cannot TA Group (explain below) | G9: Cannot TA Group (explain below) | H9: Cannot TA Group (explain below) | I9: Cannot TA Group (explain below) | J9: Cannot TA Group (explain below) | K9: Cannot TA Group (explain below) | L9: Cannot TA Group (explain below) | M9: Second Choice | N9: Cannot TA Group (explain below) | O9: Cannot TA Group (explain below) | P9: Cannot TA Group (explain below) | Q9: Cannot TA Group (explain below) | R9: Cannot TA Group (explain below) | S9: Cannot TA Group (explain below) | T9: Cannot TA Group (explain below) | U9: Cannot TA Group (explain below) | V9: Second Choice | W9: Cannot TA Group (explain below) | X9: Cannot TA Group (explain below) | Y9: Cannot TA Group (explain below) | Z9: Second Choice | AA9: Cannot TA Group (explain below) | AB9: Cannot TA Group (explain below) | AC9: First Choice Group | AD9: Cannot TA Group (explain below) | AE9: Second Choice | AF9: Cannot TA Group (explain below) | AG9: Cannot TA Group (explain below) | AH9: Cannot TA Group (explain below) | AI9: Cannot TA Group (explain below) | AJ9: Cannot TA Group (explain below) | AK9: Cannot TA Group (explain below) | AL9: Cannot TA Group (explain below) | AM9: Cannot TA Group (explain below) | AN9: Cannot TA Group (explain below) | AO9: Excellent | AP9: Unsatisfactory | AQ9: Unsatisfactory | AR9: Unsatisfactory | AS9: Excellent | AT9: Excellent | AU9: Unsatisfactory | AV9: Strong | AW9: Monday: unavailable after 3:00 PM Tuesday: unavailable after 12:00 PM-2:00PM | AX9: None | AY9: Improve public speaking or other skills | AZ9: None
A10: 46246.641 | B10: I | C10: G | D10: i@pitt.edu | E10: Cannot TA Group (explain below) | F10: Cannot TA Group (explain below) | G10: Cannot TA Group (explain below) | H10: Cannot TA Group (explain below) | I10: Cannot TA Group (explain below) | J10: Cannot TA Group (explain below) | K10: Cannot TA Group (explain below) | L10: Cannot TA Group (explain below) | M10: Cannot TA Group (explain below) | N10: Cannot TA Group (explain below) | O10: Cannot TA Group (explain below) | P10: Cannot TA Group (explain below) | Q10: Cannot TA Group (explain below) | R10: Third Choice Group | S10: Cannot TA Group (explain below) | T10: Cannot TA Group (explain below) | U10: Cannot TA Group (explain below) | V10: Third Choice Group | W10: Cannot TA Group (explain below) | X10: Cannot TA Group (explain below) | Y10: Third Choice Group | Z10: Third Choice Group | AA10: Cannot TA Group (explain below) | AB10: Cannot TA Group (explain below) | AC10: Second Choice | AD10: Second Choice | AE10: Third Choice Group | AF10: Second Choice | AG10: Second Choice | AH10: Second Choice | AI10: Cannot TA Group (explain below) | AJ10: Cannot TA Group (explain below) | AK10: First Choice Group | AL10: First Choice Group | AM10: First Choice Group | AN10: Cannot TA Group (explain below) | AO10: Excellent | AP10: Satisfactory | AQ10: Unsatisfactory | AR10: Satisfactory | AS10: Excellent | AT10: Excellent | AU10: Unsatisfactory | AV10: Satisfactory | AW10: None | AX10: Not have required background for TA: CS 2893, CS 2520, CS 2210, CS 1666, CS 1660/2060, CS 1635/2035, CS 1632, CS 1566, CS 1555/2055, CS 1510/2012, CS 1502, CS 0590, CS 0447, CS 0449 Need grading-only TA and these courses are recitation based: CS 1550, CS 1520, CS 1503, CS 1501, CS 0445, CS 0441, CMPINF 0401, CS 0011/0012, CS 0007 | AY10: Funding | AZ10: I kindly request a grading-only TA assignment, as I have multiple travel plans in the fall for conferences and personal family reasons.
A11: 46246.689 | B11: J | C11: H | D11: j@pitt.edu | E11: First Choice Group | F11: Second Choice | G11: Second Choice | H11: Third Choice Group | I11: First Choice Group | J11: Cannot TA Group (explain below) | K11: Cannot TA Group (explain below) | L11: Second Choice | M11: First Choice Group | N11: Third Choice Group | O11: Third Choice Group | P11: Cannot TA Group (explain below) | Q11: Third Choice Group | R11: Third Choice Group | S11: Cannot TA Group (explain below) | T11: Cannot TA Group (explain below) | U11: Cannot TA Group (explain below) | V11: Second Choice | W11: Third Choice Group | X11: Third Choice Group | Y11: Cannot TA Group (explain below) | Z11: First Choice Group | AA11: Cannot TA Group (explain below) | AB11: Cannot TA Group (explain below) | AC11: Second Choice | AD11: Third Choice Group | AE11: Second Choice | AF11: Third Choice Group | AG11: Cannot TA Group (explain below) | AH11: Cannot TA Group (explain below) | AI11: Cannot TA Group (explain below) | AJ11: Cannot TA Group (explain below) | AK11: Third Choice Group | AL11: Second Choice | AM11: Third Choice Group | AN11: Cannot TA Group (explain below) | AO11: Excellent | AP11: Strong | AQ11: Unsatisfactory | AR11: Satisfactory | AS11: Satisfactory | AT11: Strong | AU11: Unsatisfactory | AV11: Unsatisfactory | AW11: Schedule is flexible. Might enroll for CS 2003, if TA duty permits. | AX11: N/A | AY11: Funding, Teaching experience, Improve public speaking or other skills, Learn a new topic | AZ11: I would prefer to avoid systems courses, if possible, because my background and interests are more aligned with other areas. I would be able to contribute more effectively as a TA in those courses.
A12: 46246.7 | B12: K | C12: I | D12: k@pitt.edu | E12: First Choice Group | F12: First Choice Group | G12: First Choice Group | H12: Third Choice Group | I12: First Choice Group | J12: Third Choice Group | K12: Third Choice Group | L12: Third Choice Group | M12: Second Choice | N12: Cannot TA Group (explain below) | O12: Second Choice | P12: Cannot TA Group (explain below) | Q12: First Choice Group | R12: First Choice Group | S12: Cannot TA Group (explain below) | T12: Cannot TA Group (explain below) | U12: Cannot TA Group (explain below) | V12: Cannot TA Group (explain below) | W12: Third Choice Group | X12: First Choice Group | Y12: Second Choice | Z12: Cannot TA Group (explain below) | AA12: Cannot TA Group (explain below) | AB12: Cannot TA Group (explain below) | AC12: First Choice Group | AD12: Third Choice Group | AE12: Second Choice | AF12: First Choice Group | AG12: First Choice Group | AH12: Cannot TA Group (explain below) | AI12: Cannot TA Group (explain below) | AJ12: Cannot TA Group (explain below) | AK12: Cannot TA Group (explain below) | AL12: Second Choice | AM12: Third Choice Group | AN12: Cannot TA Group (explain below) | AO12: Excellent | AP12: Excellent | AQ12: Satisfactory | AR12: Unsatisfactory | AS12: Strong | AT12: Strong | AU12: Unsatisfactory | AV12: Satisfactory | AW12: I am not available before noon. Additionally, I am not available Fridays from 12PM-2PM due to my CS2003 requirements. | AX12: Any course listed as "Cannot TA" is because either I have never taken the course, or I do not believe my knowledge on the subject is satisfactory for the TA role. | AY12: Funding, Teaching experience, Improve public speaking or other skills, Learn a new topic | AZ12: Any course listed as "Cannot TA" is because either I have never taken the course, or I do not believe my knowledge on the subject is satisfactory for the TA role.
A13: 46246.914 | B13: L | C13: J | D13: l@pitt.edu | E13: Cannot TA Group (explain below) | F13: Cannot TA Group (explain below) | G13: Cannot TA Group (explain below) | H13: Cannot TA Group (explain below) | I13: Cannot TA Group (explain below) | J13: Cannot TA Group (explain below) | K13: Cannot TA Group (explain below) | L13: Cannot TA Group (explain below) | M13: Cannot TA Group (explain below) | N13: Cannot TA Group (explain below) | O13: Cannot TA Group (explain below) | P13: Cannot TA Group (explain below) | Q13: Cannot TA Group (explain below) | R13: Cannot TA Group (explain below) | S13: Cannot TA Group (explain below) | T13: Cannot TA Group (explain below) | U13: Cannot TA Group (explain below) | V13: Third Choice Group | W13: Cannot TA Group (explain below) | X13: Cannot TA Group (explain below) | Y13: Cannot TA Group (explain below) | Z13: Cannot TA Group (explain below) | AA13: Cannot TA Group (explain below) | AB13: Cannot TA Group (explain below) | AC13: Cannot TA Group (explain below) | AD13: Cannot TA Group (explain below) | AE13: Second Choice | AF13: Cannot TA Group (explain below) | AG13: Cannot TA Group (explain below) | AH13: Cannot TA Group (explain below) | AI13: Cannot TA Group (explain below) | AJ13: Cannot TA Group (explain below) | AK13: Second Choice | AL13: First Choice Group | AM13: Third Choice Group | AN13: Cannot TA Group (explain below) | AO13: Unsatisfactory | AP13: Unsatisfactory | AQ13: Unsatisfactory | AR13: Unsatisfactory | AS13: Unsatisfactory | AT13: Excellent | AU13: Unsatisfactory | AV13: Unsatisfactory | AW13: N/A | AX13: N/A | AY13: Funding | AZ13: Hi, my research focuses on NLP and ML, so related courses may fit my background better. Thank you!
... A24: 46254.583 | B24: X | C24: U | D24: x@pitt.edu | E24: Second Choice | F24: Second Choice | G24: Second Choice | H24: Second Choice | I24: Second Choice | J24: Second Choice | K24: Third Choice Group | L24: First Choice Group | M24: Second Choice | N24: Third Choice Group | O24: First Choice Group | P24: Second Choice | Q24: Second Choice | R24: Second Choice | S24: Second Choice | T24: First Choice Group | U24: Second Choice | V24: First Choice Group | W24: Third Choice Group | X24: Third Choice Group | Y24: Second Choice | Z24: First Choice Group | AA24: Second Choice | AB24: First Choice Group | AC24: Second Choice | AD24: First Choice Group | AE24: First Choice Group | AF24: Second Choice | AG24: Second Choice | AH24: Second Choice | AI24: Third Choice Group | AJ24: Third Choice Group | AK24: First Choice Group | AL24: First Choice Group | AM24: Cannot TA Group (explain below) | AN24: Cannot TA Group (explain below) | AO24: Excellent | AP24: Satisfactory | AQ24: Satisfactory | AR24: Satisfactory | AS24: Satisfactory | AT24: Excellent | AU24: Satisfactory | AV24: Excellent | AW24: I am unavailable from 12-3pm and 6-8:30pm Mondays, and 2pm-3:15pm on Tuesdays and Thursdays. | AX24: cs2750 | AY24: Funding | AZ24: no background in quantum computing

Sheet Cleanup
A1: =IFERROR(__xludf.DUMMYFUNCTION("{ BYCOL('Form Responses 1'!1:1, LAMBDA(header, IF(header="""", , IFERROR(REGEXEXTRACT(header, ""\[(.*)\]""), header)))); FILTER('Form Responses 1'!A2:ZZ1000, 'Form Responses 1'!A2:A1000 <> """") }"),"Timestamp") -> Timestamp | B1: =IFERROR(__xludf.DUMMYFUNCTION("""COMPUTED_VALUE"""),"First name") -> First name | C1: =IFERROR(__xludf.DUMMYFUNCTION("""COMPUTED_VALUE"""),"Last name") -> Last name | D1: =IFERROR(__xludf.DUMMYFUNCTION("""COMPUTED_VALUE"""),"Pitt email address") -> Pitt email address | E1: =IFERROR(__xludf.DUMMYFUNCTION("""COMPUTED_VALUE"""),"CS 0007") -> CS 0007 | F1: =IFERROR(__xludf.DUMMYFUNCTION("""COMPUTED_VALUE"""),"CS 0011/0012") -> CS 0011/0012 | G1: =IFERROR(__xludf.DUMMYFUNCTION("""COMPUTED_VALUE"""),"CMPINF 0401") -> CMPINF 0401 | H1: =IFERROR(__xludf.DUMMYFUNCTION("""COMPUTED_VALUE"""),"CS 0441") -> CS 0441 | I1: =IFERROR(__xludf.DUMMYFUNCTION("""COMPUTED_VALUE"""),"CS 0445") -> CS 0445 | J1: =IFERROR(__xludf.DUMMYFUNCTION("""COMPUTED_VALUE"""),"CS 0447") -> CS 0447 | K1: =IFERROR(__xludf.DUMMYFUNCTION("""COMPUTED_VALUE"""),"CS 0449") -> CS 0449 | L1: =IFERROR(__xludf.DUMMYFUNCTION("""COMPUTED_VALUE"""),"CS 0590") -> CS 0590 | M1: =IFERROR(__xludf.DUMMYFUNCTION("""COMPUTED_VALUE"""),"CS 1501") -> CS 1501 | N1: =IFERROR(__xludf.DUMMYFUNCTION("""COMPUTED_VALUE"""),"CS 1502") -> CS 1502 | O1: =IFERROR(__xludf.DUMMYFUNCTION("""COMPUTED_VALUE"""),"CS 1503") -> CS 1503 | P1: =IFERROR(__xludf.DUMMYFUNCTION("""COMPUTED_VALUE"""),"CS 1510/2012") -> CS 1510/2012 | Q1: =IFERROR(__xludf.DUMMYFUNCTION("""COMPUTED_VALUE"""),"CS 1520") -> CS 1520 | R1: =IFERROR(__xludf.DUMMYFUNCTION("""COMPUTED_VALUE"""),"CS 1530") -> CS 1530 | S1: =IFERROR(__xludf.DUMMYFUNCTION("""COMPUTED_VALUE"""),"CS 1550") -> CS 1550 | T1: =IFERROR(__xludf.DUMMYFUNCTION("""COMPUTED_VALUE"""),"CS 1555/2055") -> CS 1555/2055 | U1: =IFERROR(__xludf.DUMMYFUNCTION("""COMPUTED_VALUE"""),"CS 1566") -> CS 1566 | V1: =IFERROR(__xludf.DUMMYFUNCTION("""COMPUTED_VALUE"""),"CS 1571") -> CS 1571 | W1: =IFERROR(__xludf.DUMMYFUNCTION("""COMPUTED_VALUE"""),"CS 1632") -> CS 1632 | X1: =IFERROR(__xludf.DUMMYFUNCTION("""COMPUTED_VALUE"""),"CS 1635/2035") -> CS 1635/2035 | Y1: =IFERROR(__xludf.DUMMYFUNCTION("""COMPUTED_VALUE"""),"CS 1980/1640") -> CS 1980/1640 | Z1: =IFERROR(__xludf.DUMMYFUNCTION("""COMPUTED_VALUE"""),"CS 1656") -> CS 1656 | AA1: =IFERROR(__xludf.DUMMYFUNCTION("""COMPUTED_VALUE"""),"CS 1660/2060") -> CS 1660/2060 | AB1: =IFERROR(__xludf.DUMMYFUNCTION("""COMPUTED_VALUE"""),"CS 1666") -> CS 1666 | AC1: =IFERROR(__xludf.DUMMYFUNCTION("""COMPUTED_VALUE"""),"CS 1671/2071") -> CS 1671/2071 | AD1: =IFERROR(__xludf.DUMMYFUNCTION("""COMPUTED_VALUE"""),"CS 1674/2074") -> CS 1674/2074 | AE1: =IFERROR(__xludf.DUMMYFUNCTION("""COMPUTED_VALUE"""),"CS 1675/2075") -> CS 1675/2075 | AF1: =IFERROR(__xludf.DUMMYFUNCTION("""COMPUTED_VALUE"""),"CS 1684/2084") -> CS 1684/2084 | AG1: =IFERROR(__xludf.DUMMYFUNCTION("""COMPUTED_VALUE"""),"CS 1699") -> CS 1699 | AH1: =IFERROR(__xludf.DUMMYFUNCTION("""COMPUTED_VALUE"""),"CS 1900/1950") -> CS 1900/1950 | AI1: =IFERROR(__xludf.DUMMYFUNCTION("""COMPUTED_VALUE"""),"CS 2210") -> CS 2210 | AJ1: =IFERROR(__xludf.DUMMYFUNCTION("""COMPUTED_VALUE"""),"CS 2520") -> CS 2520 | AK1: =IFERROR(__xludf.DUMMYFUNCTION("""COMPUTED_VALUE"""),"CS 2710") -> CS 2710 | AL1: =IFERROR(__xludf.DUMMYFUNCTION("""COMPUTED_VALUE"""),"CS 2731") -> CS 2731 | AM1: =IFERROR(__xludf.DUMMYFUNCTION("""COMPUTED_VALUE"""),"CS 2750") -> CS 2750 | AN1: =IFERROR(__xludf.DUMMYFUNCTION("""COMPUTED_VALUE"""),"CS 2893") -> CS 2893 | AO1: =IFERROR(__xludf.DUMMYFUNCTION("""COMPUTED_VALUE"""),"Introductory programming (could be Python or Java)") -> Introductory programming (could be Python or Java) | AP1: =IFERROR(__xludf.DUMMYFUNCTION("""COMPUTED_VALUE"""),"Core programming in Java") -> Core programming in Java | AQ1: =IFERROR(__xludf.DUMMYFUNCTION("""COMPUTED_VALUE"""),"Computer systems/architecture") -> Computer systems/architecture | AR1: =IFERROR(__xludf.DUMMYFUNCTION("""COMPUTED_VALUE"""),"Theory and mathematical foundations") -> Theory and mathematical foundations | AS1: =IFERROR(__xludf.DUMMYFUNCTION("""COMPUTED_VALUE"""),"Programming practice and software engineering") -> Programming practice and software engineering | AT1: =IFERROR(__xludf.DUMMYFUNCTION("""COMPUTED_VALUE"""),"Artificial intelligence and machine learning") -> Artificial intelligence and machine learning | AU1: =IFERROR(__xludf.DUMMYFUNCTION("""COMPUTED_VALUE"""),"Security and networks") -> Security and networks | AV1: =IFERROR(__xludf.DUMMYFUNCTION("""COMPUTED_VALUE"""),"Data management and organization") -> Data management and organization | AW1: =IFERROR(__xludf.DUMMYFUNCTION("""COMPUTED_VALUE"""),"Scheduling constraints") -> Scheduling constraints | AX1: =IFERROR(__xludf.DUMMYFUNCTION("""COMPUTED_VALUE"""),"Courses constraints") -> Courses constraints | AY1: =IFERROR(__xludf.DUMMYFUNCTION("""COMPUTED_VALUE"""),"Goals") -> Goals | AZ1: =IFERROR(__xludf.DUMMYFUNCTION("""COMPUTED_VALUE"""),"Anything else we should know? For example: courses that you wish to avoid (explain!), etc.") -> Anything else we should know? For example: courses that you wish to avoid (explain!), etc.
A2: =IFERROR(__xludf.DUMMYFUNCTION("""COMPUTED_VALUE"""),46246.53317660879) -> 46246.533 | B2: =IFERROR(__xludf.DUMMYFUNCTION("""COMPUTED_VALUE"""),"A") -> A | C2: =IFERROR(__xludf.DUMMYFUNCTION("""COMPUTED_VALUE"""),"Y") -> Y | D2: =IFERROR(__xludf.DUMMYFUNCTION("""COMPUTED_VALUE"""),"a@pitt.edu") -> a@pitt.edu | E2: =IFERROR(__xludf.DUMMYFUNCTION("""COMPUTED_VALUE"""),"Third Choice Group") -> Third Choice Group | F2: =IFERROR(__xludf.DUMMYFUNCTION("""COMPUTED_VALUE"""),"Third Choice Group") -> Third Choice Group | G2: =IFERROR(__xludf.DUMMYFUNCTION("""COMPUTED_VALUE"""),"Third Choice Group") -> Third Choice Group | H2: =IFERROR(__xludf.DUMMYFUNCTION("""COMPUTED_VALUE"""),"Third Choice Group") -> Third Choice Group | I2: =IFERROR(__xludf.DUMMYFUNCTION("""COMPUTED_VALUE"""),"Third Choice Group") -> Third Choice Group | J2: =IFERROR(__xludf.DUMMYFUNCTION("""COMPUTED_VALUE"""),"Third Choice Group") -> Third Choice Group | K2: =IFERROR(__xludf.DUMMYFUNCTION("""COMPUTED_VALUE"""),"Third Choice Group") -> Third Choice Group | L2: =IFERROR(__xludf.DUMMYFUNCTION("""COMPUTED_VALUE"""),"Third Choice Group") -> Third Choice Group | ... W2: =IFERROR(__xludf.DUMMYFUNCTION("""COMPUTED_VALUE"""),"Third Choice Group") -> Third Choice Group | X2: =IFERROR(__xludf.DUMMYFUNCTION("""COMPUTED_VALUE"""),"First Choice Group") -> First Choice Group | Y2: =IFERROR(__xludf.DUMMYFUNCTION("""COMPUTED_VALUE"""),"Third Choice Group") -> Third Choice Group | Z2: =IFERROR(__xludf.DUMMYFUNCTION("""COMPUTED_VALUE"""),"First Choice Group") -> First Choice Group | AA2: =IFERROR(__xludf.DUMMYFUNCTION("""COMPUTED_VALUE"""),"Third Choice Group") -> Third Choice Group | AB2: =IFERROR(__xludf.DUMMYFUNCTION("""COMPUTED_VALUE"""),"Third Choice Group") -> Third Choice Group | AC2: =IFERROR(__xludf.DUMMYFUNCTION("""COMPUTED_VALUE"""),"First Choice Group") -> First Choice Group | AD2: =IFERROR(__xludf.DUMMYFUNCTION("""COMPUTED_VALUE"""),"First Choice Group") -> First Choice Group | AE2: =IFERROR(__xludf.DUMMYFUNCTION("""COMPUTED_VALUE"""),"First Choice Group") -> First Choice Group | AF2: =IFERROR(__xludf.DUMMYFUNCTION("""COMPUTED_VALUE"""),"First Choice Group") -> First Choice Group | AG2: =IFERROR(__xludf.DUMMYFUNCTION("""COMPUTED_VALUE"""),"Second Choice") -> Second Choice | AH2: =IFERROR(__xludf.DUMMYFUNCTION("""COMPUTED_VALUE"""),"Third Choice Group") -> Third Choice Group | AI2: =IFERROR(__xludf.DUMMYFUNCTION("""COMPUTED_VALUE"""),"Third Choice Group") -> Third Choice Group | AJ2: =IFERROR(__xludf.DUMMYFUNCTION("""COMPUTED_VALUE"""),"Third Choice Group") -> Third Choice Group | AK2: =IFERROR(__xludf.DUMMYFUNCTION("""COMPUTED_VALUE"""),"First Choice Group") -> First Choice Group | AL2: =IFERROR(__xludf.DUMMYFUNCTION("""COMPUTED_VALUE"""),"First Choice Group") -> First Choice Group | AM2: =IFERROR(__xludf.DUMMYFUNCTION("""COMPUTED_VALUE"""),"First Choice Group") -> First Choice Group | AN2: =IFERROR(__xludf.DUMMYFUNCTION("""COMPUTED_VALUE"""),"Third Choice Group") -> Third Choice Group | AO2: =IFERROR(__xludf.DUMMYFUNCTION("""COMPUTED_VALUE"""),"Excellent") -> Excellent | AP2: =IFERROR(__xludf.DUMMYFUNCTION("""COMPUTED_VALUE"""),"Excellent") -> Excellent | AQ2: =IFERROR(__xludf.DUMMYFUNCTION("""COMPUTED_VALUE"""),"Unsatisfactory") -> Unsatisfactory | AR2: =IFERROR(__xludf.DUMMYFUNCTION("""COMPUTED_VALUE"""),"Unsatisfactory") -> Unsatisfactory | AS2: =IFERROR(__xludf.DUMMYFUNCTION("""COMPUTED_VALUE"""),"Strong") -> Strong | AT2: =IFERROR(__xludf.DUMMYFUNCTION("""COMPUTED_VALUE"""),"Excellent") -> Excellent | AU2: =IFERROR(__xludf.DUMMYFUNCTION("""COMPUTED_VALUE"""),"Satisfactory") -> Satisfactory | AV2: =IFERROR(__xludf.DUMMYFUNCTION("""COMPUTED_VALUE"""),"Strong") -> Strong | AW2: =IFERROR(__xludf.DUMMYFUNCTION("""COMPUTED_VALUE"""),"Friday 12-4PM") -> Friday 12-4PM | AX2: =IFERROR(__xludf.DUMMYFUNCTION("""COMPUTED_VALUE"""),"N/A") -> N/A | AY2: =IFERROR(__xludf.DUMMYFUNCTION("""COMPUTED_VALUE"""),"Funding, Teaching experience") -> Funding, Teaching experience | AZ2: =IFERROR(__xludf.DUMMYFUNCTION("""COMPUTED_VALUE"""),"CS1503 or 1555 since I find it hard to work with Dr Marina Barsky - great person, but hard to work with because it’s very hard to convince her on any changes on course structure ") -> CS1503 or 1555 since I find it hard to work with Dr Marina Barsky - great person, but hard to work with because it’s very hard to convince her on any changes on course structure
A3: =IFERROR(__xludf.DUMMYFUNCTION("""COMPUTED_VALUE"""),46246.55689633102) -> 46246.557 | B3: =IFERROR(__xludf.DUMMYFUNCTION("""COMPUTED_VALUE"""),"B") -> B | C3: =IFERROR(__xludf.DUMMYFUNCTION("""COMPUTED_VALUE"""),"Z") -> Z | D3: =IFERROR(__xludf.DUMMYFUNCTION("""COMPUTED_VALUE"""),"b@pitt.edu") -> b@pitt.edu | E3: =IFERROR(__xludf.DUMMYFUNCTION("""COMPUTED_VALUE"""),"First Choice Group") -> First Choice Group | F3: =IFERROR(__xludf.DUMMYFUNCTION("""COMPUTED_VALUE"""),"First Choice Group") -> First Choice Group | G3: =IFERROR(__xludf.DUMMYFUNCTION("""COMPUTED_VALUE"""),"First Choice Group") -> First Choice Group | H3: =IFERROR(__xludf.DUMMYFUNCTION("""COMPUTED_VALUE"""),"First Choice Group") -> First Choice Group | I3: =IFERROR(__xludf.DUMMYFUNCTION("""COMPUTED_VALUE"""),"First Choice Group") -> First Choice Group | J3: =IFERROR(__xludf.DUMMYFUNCTION("""COMPUTED_VALUE"""),"Third Choice Group") -> Third Choice Group | K3: =IFERROR(__xludf.DUMMYFUNCTION("""COMPUTED_VALUE"""),"First Choice Group") -> First Choice Group | L3: =IFERROR(__xludf.DUMMYFUNCTION("""COMPUTED_VALUE"""),"Third Choice Group") -> Third Choice Group | M3: =IFERROR(__xludf.DUMMYFUNCTION("""COMPUTED_VALUE"""),"First Choice Group") -> First Choice Group | N3: =IFERROR(__xludf.DUMMYFUNCTION("""COMPUTED_VALUE"""),"Third Choice Group") -> Third Choice Group | O3: =IFERROR(__xludf.DUMMYFUNCTION("""COMPUTED_VALUE"""),"Third Choice Group") -> Third Choice Group | P3: =IFERROR(__xludf.DUMMYFUNCTION("""COMPUTED_VALUE"""),"First Choice Group") -> First Choice Group | Q3: =IFERROR(__xludf.DUMMYFUNCTION("""COMPUTED_VALUE"""),"First Choice Group") -> First Choice Group | R3: =IFERROR(__xludf.DUMMYFUNCTION("""COMPUTED_VALUE"""),"Third Choice Group") -> Third Choice Group | S3: =IFERROR(__xludf.DUMMYFUNCTION("""COMPUTED_VALUE"""),"First Choice Group") -> First Choice Group | T3: =IFERROR(__xludf.DUMMYFUNCTION("""COMPUTED_VALUE"""),"First Choice Group") -> First Choice Group | U3: =IFERROR(__xludf.DUMMYFUNCTION("""COMPUTED_VALUE"""),"Third Choice Group") -> Third Choice Group | V3: =IFERROR(__xludf.DUMMYFUNCTION("""COMPUTED_VALUE"""),"Third Choice Group") -> Third Choice Group | W3: =IFERROR(__xludf.DUMMYFUNCTION("""COMPUTED_VALUE"""),"Third Choice Group") -> Third Choice Group | X3: =IFERROR(__xludf.DUMMYFUNCTION("""COMPUTED_VALUE"""),"Third Choice Group") -> Third Choice Group | Y3: =IFERROR(__xludf.DUMMYFUNCTION("""COMPUTED_VALUE"""),"Third Choice Group") -> Third Choice Group | Z3: =IFERROR(__xludf.DUMMYFUNCTION("""COMPUTED_VALUE"""),"First Choice Group") -> First Choice Group | AA3: =IFERROR(__xludf.DUMMYFUNCTION("""COMPUTED_VALUE"""),"Second Choice") -> Second Choice | AB3: =IFERROR(__xludf.DUMMYFUNCTION("""COMPUTED_VALUE"""),"Second Choice") -> Second Choice | AC3: =IFERROR(__xludf.DUMMYFUNCTION("""COMPUTED_VALUE"""),"Second Choice") -> Second Choice | AD3: =IFERROR(__xludf.DUMMYFUNCTION("""COMPUTED_VALUE"""),"Second Choice") -> Second Choice | AE3: =IFERROR(__xludf.DUMMYFUNCTION("""COMPUTED_VALUE"""),"Second Choice") -> Second Choice | AF3: =IFERROR(__xludf.DUMMYFUNCTION("""COMPUTED_VALUE"""),"Second Choice") -> Second Choice | AG3: =IFERROR(__xludf.DUMMYFUNCTION("""COMPUTED_VALUE"""),"Second Choice") -> Second Choice | AH3: =IFERROR(__xludf.DUMMYFUNCTION("""COMPUTED_VALUE"""),"Second Choice") -> Second Choice | AI3: =IFERROR(__xludf.DUMMYFUNCTION("""COMPUTED_VALUE"""),"Third Choice Group") -> Third Choice Group | AJ3: =IFERROR(__xludf.DUMMYFUNCTION("""COMPUTED_VALUE"""),"Second Choice") -> Second Choice | AK3: =IFERROR(__xludf.DUMMYFUNCTION("""COMPUTED_VALUE"""),"Second Choice") -> Second Choice | AL3: =IFERROR(__xludf.DUMMYFUNCTION("""COMPUTED_VALUE"""),"Second Choice") -> Second Choice | AM3: =IFERROR(__xludf.DUMMYFUNCTION("""COMPUTED_VALUE"""),"Second Choice") -> Second Choice | AN3: =IFERROR(__xludf.DUMMYFUNCTION("""COMPUTED_VALUE"""),"Third Choice Group") -> Third Choice Group | AO3: =IFERROR(__xludf.DUMMYFUNCTION("""COMPUTED_VALUE"""),"Strong") -> Strong | AP3: =IFERROR(__xludf.DUMMYFUNCTION("""COMPUTED_VALUE"""),"Strong") -> Strong | AQ3: =IFERROR(__xludf.DUMMYFUNCTION("""COMPUTED_VALUE"""),"Satisfactory") -> Satisfactory | AR3: =IFERROR(__xludf.DUMMYFUNCTION("""COMPUTED_VALUE"""),"Unsatisfactory") -> Unsatisfactory | AS3: =IFERROR(__xludf.DUMMYFUNCTION("""COMPUTED_VALUE"""),"Strong") -> Strong | AT3: =IFERROR(__xludf.DUMMYFUNCTION("""COMPUTED_VALUE"""),"Strong") -> Strong | AU3: =IFERROR(__xludf.DUMMYFUNCTION("""COMPUTED_VALUE"""),"Strong") -> Strong | AV3: =IFERROR(__xludf.DUMMYFUNCTION("""COMPUTED_VALUE"""),"Strong") -> Strong | AW3: =IFERROR(__xludf.DUMMYFUNCTION("""COMPUTED_VALUE"""),"Monday: 11:00 AM–12:15 PM; 6:00–8:30 PM Tuesday: 1:00–1:30 PM; 4:00–5:15 PM Wednesday: 11:00 AM–12:15 PM Thursday: 4:00–5:15 PM Friday: 1:00–1:30 PM") -> Monday: 11:00 AM–12:15 PM; 6:00–8:30 PM Tuesday: 1:00–1:30 PM; 4:00–5:15 PM Wednesday: 11:00 AM–12:15 PM Thursday: 4:00–5:15 PM Friday: 1:00–1:30 PM | AX3: =IFERROR(__xludf.DUMMYFUNCTION("""COMPUTED_VALUE"""),"CS 2710: Foundations of Artificial Intelligence CS 2750: Machine Learning CS 2893: Modern Quantum Computing CS 2990: Independent Study") -> CS 2710: Foundations of Artificial Intelligence CS 2750: Machine Learning CS 2893: Modern Quantum Computing CS 2990: Independent Study | AY3: =IFERROR(__xludf.DUMMYFUNCTION("""COMPUTED_VALUE"""),"Funding, Learn a new topic") -> Funding, Learn a new topic | AZ3: =IFERROR(__xludf.DUMMYFUNCTION("""COMPUTED_VALUE"""),"Avoid theory topic; Not interested in teaching ; Thank you very much! ;)") -> Avoid theory topic; Not interested in teaching ; Thank you very much! ;)
A4: =IFERROR(__xludf.DUMMYFUNCTION("""COMPUTED_VALUE"""),46246.55808) -> 46246.558 | B4: =IFERROR(__xludf.DUMMYFUNCTION("""COMPUTED_VALUE"""),"C") -> C | C4: =IFERROR(__xludf.DUMMYFUNCTION("""COMPUTED_VALUE"""),"A") -> A | D4: =IFERROR(__xludf.DUMMYFUNCTION("""COMPUTED_VALUE"""),"c@pitt.edu") -> c@pitt.edu | E4: =IFERROR(__xludf.DUMMYFUNCTION("""COMPUTED_VALUE"""),"Third Choice Group") -> Third Choice Group | F4: =IFERROR(__xludf.DUMMYFUNCTION("""COMPUTED_VALUE"""),"Third Choice Group") -> Third Choice Group | G4: =IFERROR(__xludf.DUMMYFUNCTION("""COMPUTED_VALUE"""),"Third Choice Group") -> Third Choice Group | H4: =IFERROR(__xludf.DUMMYFUNCTION("""COMPUTED_VALUE"""),"Third Choice Group") -> Third Choice Group | I4: =IFERROR(__xludf.DUMMYFUNCTION("""COMPUTED_VALUE"""),"Second Choice") -> Second Choice | J4: =IFERROR(__xludf.DUMMYFUNCTION("""COMPUTED_VALUE"""),"Third Choice Group") -> Third Choice Group | K4: =IFERROR(__xludf.DUMMYFUNCTION("""COMPUTED_VALUE"""),"Third Choice Group") -> Third Choice Group | L4: =IFERROR(__xludf.DUMMYFUNCTION("""COMPUTED_VALUE"""),"Third Choice Group") -> Third Choice Group | M4: =IFERROR(__xludf.DUMMYFUNCTION("""COMPUTED_VALUE"""),"Third Choice Group") -> Third Choice Group | N4: =IFERROR(__xludf.DUMMYFUNCTION("""COMPUTED_VALUE"""),"Third Choice Group") -> Third Choice Group | O4: =IFERROR(__xludf.DUMMYFUNCTION("""COMPUTED_VALUE"""),"Third Choice Group") -> Third Choice Group | P4: =IFERROR(__xludf.DUMMYFUNCTION("""COMPUTED_VALUE"""),"Third Choice Group") -> Third Choice Group | Q4: =IFERROR(__xludf.DUMMYFUNCTION("""COMPUTED_VALUE"""),"Second Choice") -> Second Choice | R4: =IFERROR(__xludf.DUMMYFUNCTION("""COMPUTED_VALUE"""),"Third Choice Group") -> Third Choice Group | S4: =IFERROR(__xludf.DUMMYFUNCTION("""COMPUTED_VALUE"""),"Second Choice") -> Second Choice | T4: =IFERROR(__xludf.DUMMYFUNCTION("""COMPUTED_VALUE"""),"Third Choice Group") -> Third Choice Group | U4: =IFERROR(__xludf.DUMMYFUNCTION("""COMPUTED_VALUE"""),"Third Choice Group") -> Third Choice Group | V4: =IFERROR(__xludf.DUMMYFUNCTION("""COMPUTED_VALUE"""),"Third Choice Group") -> Third Choice Group | W4: =IFERROR(__xludf.DUMMYFUNCTION("""COMPUTED_VALUE"""),"Third Choice Group") -> Third Choice Group | X4: =IFERROR(__xludf.DUMMYFUNCTION("""COMPUTED_VALUE"""),"Third Choice Group") -> Third Choice Group | Y4: =IFERROR(__xludf.DUMMYFUNCTION("""COMPUTED_VALUE"""),"Third Choice Group") -> Third Choice Group | Z4: =IFERROR(__xludf.DUMMYFUNCTION("""COMPUTED_VALUE"""),"First Choice Group") -> First Choice Group | AA4: =IFERROR(__xludf.DUMMYFUNCTION("""COMPUTED_VALUE"""),"Third Choice Group") -> Third Choice Group | AB4: =IFERROR(__xludf.DUMMYFUNCTION("""COMPUTED_VALUE"""),"Third Choice Group") -> Third Choice Group | AC4: =IFERROR(__xludf.DUMMYFUNCTION("""COMPUTED_VALUE"""),"Third Choice Group") -> Third Choice Group | AD4: =IFERROR(__xludf.DUMMYFUNCTION("""COMPUTED_VALUE"""),"Third Choice Group") -> Third Choice Group | AE4: =IFERROR(__xludf.DUMMYFUNCTION("""COMPUTED_VALUE"""),"Third Choice Group") -> Third Choice Group | AF4: =IFERROR(__xludf.DUMMYFUNCTION("""COMPUTED_VALUE"""),"Third Choice Group") -> Third Choice Group | AG4: =IFERROR(__xludf.DUMMYFUNCTION("""COMPUTED_VALUE"""),"Third Choice Group") -> Third Choice Group | AH4: =IFERROR(__xludf.DUMMYFUNCTION("""COMPUTED_VALUE"""),"Third Choice Group") -> Third Choice Group | ... AN4: =IFERROR(__xludf.DUMMYFUNCTION("""COMPUTED_VALUE"""),"Third Choice Group") -> Third Choice Group | AO4: =IFERROR(__xludf.DUMMYFUNCTION("""COMPUTED_VALUE"""),"Excellent") -> Excellent | AP4: =IFERROR(__xludf.DUMMYFUNCTION("""COMPUTED_VALUE"""),"Excellent") -> Excellent | AQ4: =IFERROR(__xludf.DUMMYFUNCTION("""COMPUTED_VALUE"""),"Strong") -> Strong | AR4: =IFERROR(__xludf.DUMMYFUNCTION("""COMPUTED_VALUE"""),"Unsatisfactory") -> Unsatisfactory | AS4: =IFERROR(__xludf.DUMMYFUNCTION("""COMPUTED_VALUE"""),"Excellent") -> Excellent | AT4: =IFERROR(__xludf.DUMMYFUNCTION("""COMPUTED_VALUE"""),"Strong") -> Strong | AU4: =IFERROR(__xludf.DUMMYFUNCTION("""COMPUTED_VALUE"""),"Satisfactory") -> Satisfactory | AV4: =IFERROR(__xludf.DUMMYFUNCTION("""COMPUTED_VALUE"""),"Excellent") -> Excellent | AW4: =IFERROR(__xludf.DUMMYFUNCTION("""COMPUTED_VALUE"""),"No real constraints") -> No real constraints | AX4: =IFERROR(__xludf.DUMMYFUNCTION("""COMPUTED_VALUE"""),"No conflicts") -> No conflicts | AY4: =IFERROR(__xludf.DUMMYFUNCTION("""COMPUTED_VALUE"""),"Funding, Teaching experience") -> Funding, Teaching experience | AZ4: =IFERROR(__xludf.DUMMYFUNCTION("""COMPUTED_VALUE"""),"If there are multiple sections of cs1656, I prefer to be assigned to the one of Dr. Labrinidis") -> If there are multiple sections of cs1656, I prefer to be assigned to the one of Dr. Labrinidis
A5: =IFERROR(__xludf.DUMMYFUNCTION("""COMPUTED_VALUE"""),46246.57346724537) -> 46246.573 | B5: =IFERROR(__xludf.DUMMYFUNCTION("""COMPUTED_VALUE"""),"D") -> D | C5: =IFERROR(__xludf.DUMMYFUNCTION("""COMPUTED_VALUE"""),"B") -> B | D5: =IFERROR(__xludf.DUMMYFUNCTION("""COMPUTED_VALUE"""),"d@pitt.edu") -> d@pitt.edu | E5: =IFERROR(__xludf.DUMMYFUNCTION("""COMPUTED_VALUE"""),"First Choice Group") -> First Choice Group | F5: =IFERROR(__xludf.DUMMYFUNCTION("""COMPUTED_VALUE"""),"First Choice Group") -> First Choice Group | G5: =IFERROR(__xludf.DUMMYFUNCTION("""COMPUTED_VALUE"""),"First Choice Group") -> First Choice Group | H5: =IFERROR(__xludf.DUMMYFUNCTION("""COMPUTED_VALUE"""),"First Choice Group") -> First Choice Group | I5: =IFERROR(__xludf.DUMMYFUNCTION("""COMPUTED_VALUE"""),"Cannot TA Group (explain below)") -> Cannot TA Group (explain below) | J5: =IFERROR(__xludf.DUMMYFUNCTION("""COMPUTED_VALUE"""),"Cannot TA Group (explain below)") -> Cannot TA Group (explain below) | K5: =IFERROR(__xludf.DUMMYFUNCTION("""COMPUTED_VALUE"""),"Cannot TA Group (explain below)") -> Cannot TA Group (explain below) | L5: =IFERROR(__xludf.DUMMYFUNCTION("""COMPUTED_VALUE"""),"First Choice Group") -> First Choice Group | M5: =IFERROR(__xludf.DUMMYFUNCTION("""COMPUTED_VALUE"""),"Cannot TA Group (explain below)") -> Cannot TA Group (explain below) | N5: =IFERROR(__xludf.DUMMYFUNCTION("""COMPUTED_VALUE"""),"Cannot TA Group (explain below)") -> Cannot TA Group (explain below) | O5: =IFERROR(__xludf.DUMMYFUNCTION("""COMPUTED_VALUE"""),"First Choice Group") -> First Choice Group | P5: =IFERROR(__xludf.DUMMYFUNCTION("""COMPUTED_VALUE"""),"Cannot TA Group (explain below)") -> Cannot TA Group (explain below) | Q5: =IFERROR(__xludf.DUMMYFUNCTION("""COMPUTED_VALUE"""),"First Choice Group") -> First Choice Group | R5: =IFERROR(__xludf.DUMMYFUNCTION("""COMPUTED_VALUE"""),"First Choice Group") -> First Choice Group | S5: =IFERROR(__xludf.DUMMYFUNCTION("""COMPUTED_VALUE"""),"Cannot TA Group (explain below)") -> Cannot TA Group (explain below) | T5: =IFERROR(__xludf.DUMMYFUNCTION("""COMPUTED_VALUE"""),"Cannot TA Group (explain below)") -> Cannot TA Group (explain below) | U5: =IFERROR(__xludf.DUMMYFUNCTION("""COMPUTED_VALUE"""),"Cannot TA Group (explain below)") -> Cannot TA Group (explain below) | V5: =IFERROR(__xludf.DUMMYFUNCTION("""COMPUTED_VALUE"""),"First Choice Group") -> First Choice Group | W5: =IFERROR(__xludf.DUMMYFUNCTION("""COMPUTED_VALUE"""),"First Choice Group") -> First Choice Group | X5: =IFERROR(__xludf.DUMMYFUNCTION("""COMPUTED_VALUE"""),"First Choice Group") -> First Choice Group | Y5: =IFERROR(__xludf.DUMMYFUNCTION("""COMPUTED_VALUE"""),"First Choice Group") -> First Choice Group | Z5: =IFERROR(__xludf.DUMMYFUNCTION("""COMPUTED_VALUE"""),"First Choice Group") -> First Choice Group | AA5: =IFERROR(__xludf.DUMMYFUNCTION("""COMPUTED_VALUE"""),"First Choice Group") -> First Choice Group | AB5: =IFERROR(__xludf.DUMMYFUNCTION("""COMPUTED_VALUE"""),"First Choice Group") -> First Choice Group | AC5: =IFERROR(__xludf.DUMMYFUNCTION("""COMPUTED_VALUE"""),"First Choice Group") -> First Choice Group | ... AH5: =IFERROR(__xludf.DUMMYFUNCTION("""COMPUTED_VALUE"""),"First Choice Group") -> First Choice Group | AI5: =IFERROR(__xludf.DUMMYFUNCTION("""COMPUTED_VALUE"""),"Cannot TA Group (explain below)") -> Cannot TA Group (explain below) | AJ5: =IFERROR(__xludf.DUMMYFUNCTION("""COMPUTED_VALUE"""),"Cannot TA Group (explain below)") -> Cannot TA Group (explain below) | AK5: =IFERROR(__xludf.DUMMYFUNCTION("""COMPUTED_VALUE"""),"First Choice Group") -> First Choice Group | AL5: =IFERROR(__xludf.DUMMYFUNCTION("""COMPUTED_VALUE"""),"First Choice Group") -> First Choice Group | AM5: =IFERROR(__xludf.DUMMYFUNCTION("""COMPUTED_VALUE"""),"First Choice Group") -> First Choice Group | AN5: =IFERROR(__xludf.DUMMYFUNCTION("""COMPUTED_VALUE"""),"Cannot TA Group (explain below)") -> Cannot TA Group (explain below) | AO5: =IFERROR(__xludf.DUMMYFUNCTION("""COMPUTED_VALUE"""),"Excellent") -> Excellent | AP5: =IFERROR(__xludf.DUMMYFUNCTION("""COMPUTED_VALUE"""),"Excellent") -> Excellent | AQ5: =IFERROR(__xludf.DUMMYFUNCTION("""COMPUTED_VALUE"""),"Unsatisfactory") -> Unsatisfactory | AR5: =IFERROR(__xludf.DUMMYFUNCTION("""COMPUTED_VALUE"""),"Unsatisfactory") -> Unsatisfactory | AS5: =IFERROR(__xludf.DUMMYFUNCTION("""COMPUTED_VALUE"""),"Unsatisfactory") -> Unsatisfactory | AT5: =IFERROR(__xludf.DUMMYFUNCTION("""COMPUTED_VALUE"""),"Excellent") -> Excellent | AU5: =IFERROR(__xludf.DUMMYFUNCTION("""COMPUTED_VALUE"""),"Unsatisfactory") -> Unsatisfactory | AV5: =IFERROR(__xludf.DUMMYFUNCTION("""COMPUTED_VALUE"""),"Unsatisfactory") -> Unsatisfactory | AW5: =IFERROR(__xludf.DUMMYFUNCTION("""COMPUTED_VALUE"""),"Not available Monday Tuesday Wednesday (all day); only available Thursday afternoon and Friday (all day)") -> Not available Monday Tuesday Wednesday (all day); only available Thursday afternoon and Friday (all day) | AX5: =IFERROR(__xludf.DUMMYFUNCTION("""COMPUTED_VALUE"""),"Cannot do algorithms, systems or architecture courses; only can do introductory programing courses ") -> Cannot do algorithms, systems or architecture courses; only can do introductory programing courses | AY5: =IFERROR(__xludf.DUMMYFUNCTION("""COMPUTED_VALUE"""),"Funding, Teaching experience, Improve public speaking or other skills") -> Funding, Teaching experience, Improve public speaking or other skills | AZ5: =IFERROR(__xludf.DUMMYFUNCTION("""COMPUTED_VALUE"""),"definitely want to avoid - assembly language, architecture, formal methods, algorithms, systems courses; prefer intro programming, data science, hci or ai courses!") -> definitely want to avoid - assembly language, architecture, formal methods, algorithms, systems courses; prefer intro programming, data science, hci or ai courses!
A6: =IFERROR(__xludf.DUMMYFUNCTION("""COMPUTED_VALUE"""),46246.57361850694) -> 46246.574 | B6: =IFERROR(__xludf.DUMMYFUNCTION("""COMPUTED_VALUE"""),"E") -> E | C6: =IFERROR(__xludf.DUMMYFUNCTION("""COMPUTED_VALUE"""),"C") -> C | D6: =IFERROR(__xludf.DUMMYFUNCTION("""COMPUTED_VALUE"""),"e@pitt.edu") -> e@pitt.edu | E6: =IFERROR(__xludf.DUMMYFUNCTION("""COMPUTED_VALUE"""),"Third Choice Group") -> Third Choice Group | F6: =IFERROR(__xludf.DUMMYFUNCTION("""COMPUTED_VALUE"""),"Third Choice Group") -> Third Choice Group | G6: =IFERROR(__xludf.DUMMYFUNCTION("""COMPUTED_VALUE"""),"Third Choice Group") -> Third Choice Group | H6: =IFERROR(__xludf.DUMMYFUNCTION("""COMPUTED_VALUE"""),"Third Choice Group") -> Third Choice Group | I6: =IFERROR(__xludf.DUMMYFUNCTION("""COMPUTED_VALUE"""),"Third Choice Group") -> Third Choice Group | J6: =IFERROR(__xludf.DUMMYFUNCTION("""COMPUTED_VALUE"""),"Third Choice Group") -> Third Choice Group | K6: =IFERROR(__xludf.DUMMYFUNCTION("""COMPUTED_VALUE"""),"Third Choice Group") -> Third Choice Group | L6: =IFERROR(__xludf.DUMMYFUNCTION("""COMPUTED_VALUE"""),"Third Choice Group") -> Third Choice Group | ... U6: =IFERROR(__xludf.DUMMYFUNCTION("""COMPUTED_VALUE"""),"Third Choice Group") -> Third Choice Group | V6: =IFERROR(__xludf.DUMMYFUNCTION("""COMPUTED_VALUE"""),"Second Choice") -> Second Choice | W6: =IFERROR(__xludf.DUMMYFUNCTION("""COMPUTED_VALUE"""),"Third Choice Group") -> Third Choice Group | X6: =IFERROR(__xludf.DUMMYFUNCTION("""COMPUTED_VALUE"""),"Third Choice Group") -> Third Choice Group | Y6: =IFERROR(__xludf.DUMMYFUNCTION("""COMPUTED_VALUE"""),"Third Choice Group") -> Third Choice Group | Z6: =IFERROR(__xludf.DUMMYFUNCTION("""COMPUTED_VALUE"""),"Second Choice") -> Second Choice | AA6: =IFERROR(__xludf.DUMMYFUNCTION("""COMPUTED_VALUE"""),"Third Choice Group") -> Third Choice Group | AB6: =IFERROR(__xludf.DUMMYFUNCTION("""COMPUTED_VALUE"""),"Third Choice Group") -> Third Choice Group | AC6: =IFERROR(__xludf.DUMMYFUNCTION("""COMPUTED_VALUE"""),"Second Choice") -> Second Choice | AD6: =IFERROR(__xludf.DUMMYFUNCTION("""COMPUTED_VALUE"""),"Second Choice") -> Second Choice | AE6: =IFERROR(__xludf.DUMMYFUNCTION("""COMPUTED_VALUE"""),"Second Choice") -> Second Choice | AF6: =IFERROR(__xludf.DUMMYFUNCTION("""COMPUTED_VALUE"""),"Third Choice Group") -> Third Choice Group | AG6: =IFERROR(__xludf.DUMMYFUNCTION("""COMPUTED_VALUE"""),"Third Choice Group") -> Third Choice Group | AH6: =IFERROR(__xludf.DUMMYFUNCTION("""COMPUTED_VALUE"""),"Third Choice Group") -> Third Choice Group | AI6: =IFERROR(__xludf.DUMMYFUNCTION("""COMPUTED_VALUE"""),"Third Choice Group") -> Third Choice Group | AJ6: =IFERROR(__xludf.DUMMYFUNCTION("""COMPUTED_VALUE"""),"Cannot TA Group (explain below)") -> Cannot TA Group (explain below) | AK6: =IFERROR(__xludf.DUMMYFUNCTION("""COMPUTED_VALUE"""),"First Choice Group") -> First Choice Group | AL6: =IFERROR(__xludf.DUMMYFUNCTION("""COMPUTED_VALUE"""),"Second Choice") -> Second Choice | AM6: =IFERROR(__xludf.DUMMYFUNCTION("""COMPUTED_VALUE"""),"First Choice Group") -> First Choice Group | AN6: =IFERROR(__xludf.DUMMYFUNCTION("""COMPUTED_VALUE"""),"Cannot TA Group (explain below)") -> Cannot TA Group (explain below) | AO6: =IFERROR(__xludf.DUMMYFUNCTION("""COMPUTED_VALUE"""),"Satisfactory") -> Satisfactory | AP6: =IFERROR(__xludf.DUMMYFUNCTION("""COMPUTED_VALUE"""),"Satisfactory") -> Satisfactory | AQ6: =IFERROR(__xludf.DUMMYFUNCTION("""COMPUTED_VALUE"""),"Satisfactory") -> Satisfactory | AR6: =IFERROR(__xludf.DUMMYFUNCTION("""COMPUTED_VALUE"""),"Satisfactory") -> Satisfactory | AS6: =IFERROR(__xludf.DUMMYFUNCTION("""COMPUTED_VALUE"""),"Strong") -> Strong | AT6: =IFERROR(__xludf.DUMMYFUNCTION("""COMPUTED_VALUE"""),"Excellent") -> Excellent | AU6: =IFERROR(__xludf.DUMMYFUNCTION("""COMPUTED_VALUE"""),"Unsatisfactory") -> Unsatisfactory | AV6: =IFERROR(__xludf.DUMMYFUNCTION("""COMPUTED_VALUE"""),"Satisfactory") -> Satisfactory | AW6: =IFERROR(__xludf.DUMMYFUNCTION("""COMPUTED_VALUE"""),"Potential conferences that I may have to make time for: NeurIPS (Dec 6-13). This can be limited to a few days depending if/when we have to present.") -> Potential conferences that I may have to make time for: NeurIPS (Dec 6-13). This can be limited to a few days depending if/when we have to present. | AX6: =IFERROR(__xludf.DUMMYFUNCTION("""COMPUTED_VALUE"""),"NA") -> NA | AY6: =IFERROR(__xludf.DUMMYFUNCTION("""COMPUTED_VALUE"""),"Funding") -> Funding | AZ6: =IFERROR(__xludf.DUMMYFUNCTION("""COMPUTED_VALUE"""),"Only because of my limited understanding about these topics: MODERN QUANTUM COMPUTING, WIDE AREA NETWORKS.") -> Only because of my limited understanding about these topics: MODERN QUANTUM COMPUTING, WIDE AREA NETWORKS.
A7: =IFERROR(__xludf.DUMMYFUNCTION("""COMPUTED_VALUE"""),46246.57415534722) -> 46246.574 | B7: =IFERROR(__xludf.DUMMYFUNCTION("""COMPUTED_VALUE"""),"F") -> F | C7: =IFERROR(__xludf.DUMMYFUNCTION("""COMPUTED_VALUE"""),"D") -> D | D7: =IFERROR(__xludf.DUMMYFUNCTION("""COMPUTED_VALUE"""),"f@pitt.edu") -> f@pitt.edu | E7: =IFERROR(__xludf.DUMMYFUNCTION("""COMPUTED_VALUE"""),"Third Choice Group") -> Third Choice Group | F7: =IFERROR(__xludf.DUMMYFUNCTION("""COMPUTED_VALUE"""),"Third Choice Group") -> Third Choice Group | G7: =IFERROR(__xludf.DUMMYFUNCTION("""COMPUTED_VALUE"""),"Third Choice Group") -> Third Choice Group | H7: =IFERROR(__xludf.DUMMYFUNCTION("""COMPUTED_VALUE"""),"Third Choice Group") -> Third Choice Group | I7: =IFERROR(__xludf.DUMMYFUNCTION("""COMPUTED_VALUE"""),"Third Choice Group") -> Third Choice Group | J7: =IFERROR(__xludf.DUMMYFUNCTION("""COMPUTED_VALUE"""),"Third Choice Group") -> Third Choice Group | K7: =IFERROR(__xludf.DUMMYFUNCTION("""COMPUTED_VALUE"""),"Third Choice Group") -> Third Choice Group | L7: =IFERROR(__xludf.DUMMYFUNCTION("""COMPUTED_VALUE"""),"Third Choice Group") -> Third Choice Group | ... O7: =IFERROR(__xludf.DUMMYFUNCTION("""COMPUTED_VALUE"""),"Third Choice Group") -> Third Choice Group | P7: =IFERROR(__xludf.DUMMYFUNCTION("""COMPUTED_VALUE"""),"Second Choice") -> Second Choice | Q7: =IFERROR(__xludf.DUMMYFUNCTION("""COMPUTED_VALUE"""),"Third Choice Group") -> Third Choice Group | R7: =IFERROR(__xludf.DUMMYFUNCTION("""COMPUTED_VALUE"""),"Third Choice Group") -> Third Choice Group | S7: =IFERROR(__xludf.DUMMYFUNCTION("""COMPUTED_VALUE"""),"Third Choice Group") -> Third Choice Group | T7: =IFERROR(__xludf.DUMMYFUNCTION("""COMPUTED_VALUE"""),"Third Choice Group") -> Third Choice Group | U7: =IFERROR(__xludf.DUMMYFUNCTION("""COMPUTED_VALUE"""),"Third Choice Group") -> Third Choice Group | V7: =IFERROR(__xludf.DUMMYFUNCTION("""COMPUTED_VALUE"""),"Second Choice") -> Second Choice | W7: =IFERROR(__xludf.DUMMYFUNCTION("""COMPUTED_VALUE"""),"Third Choice Group") -> Third Choice Group | X7: =IFERROR(__xludf.DUMMYFUNCTION("""COMPUTED_VALUE"""),"Third Choice Group") -> Third Choice Group | Y7: =IFERROR(__xludf.DUMMYFUNCTION("""COMPUTED_VALUE"""),"Third Choice Group") -> Third Choice Group | Z7: =IFERROR(__xludf.DUMMYFUNCTION("""COMPUTED_VALUE"""),"Second Choice") -> Second Choice | AA7: =IFERROR(__xludf.DUMMYFUNCTION("""COMPUTED_VALUE"""),"Third Choice Group") -> Third Choice Group | AB7: =IFERROR(__xludf.DUMMYFUNCTION("""COMPUTED_VALUE"""),"Third Choice Group") -> Third Choice Group | AC7: =IFERROR(__xludf.DUMMYFUNCTION("""COMPUTED_VALUE"""),"Third Choice Group") -> Third Choice Group | AD7: =IFERROR(__xludf.DUMMYFUNCTION("""COMPUTED_VALUE"""),"First Choice Group") -> First Choice Group | AE7: =IFERROR(__xludf.DUMMYFUNCTION("""COMPUTED_VALUE"""),"Cannot TA Group (explain below)") -> Cannot TA Group (explain below) | AF7: =IFERROR(__xludf.DUMMYFUNCTION("""COMPUTED_VALUE"""),"Third Choice Group") -> Third Choice Group | AG7: =IFERROR(__xludf.DUMMYFUNCTION("""COMPUTED_VALUE"""),"Third Choice Group") -> Third Choice Group | AH7: =IFERROR(__xludf.DUMMYFUNCTION("""COMPUTED_VALUE"""),"Third Choice Group") -> Third Choice Group | AI7: =IFERROR(__xludf.DUMMYFUNCTION("""COMPUTED_VALUE"""),"Third Choice Group") -> Third Choice Group | AJ7: =IFERROR(__xludf.DUMMYFUNCTION("""COMPUTED_VALUE"""),"Third Choice Group") -> Third Choice Group | AK7: =IFERROR(__xludf.DUMMYFUNCTION("""COMPUTED_VALUE"""),"Third Choice Group") -> Third Choice Group | AL7: =IFERROR(__xludf.DUMMYFUNCTION("""COMPUTED_VALUE"""),"Third Choice Group") -> Third Choice Group | AM7: =IFERROR(__xludf.DUMMYFUNCTION("""COMPUTED_VALUE"""),"First Choice Group") -> First Choice Group | AN7: =IFERROR(__xludf.DUMMYFUNCTION("""COMPUTED_VALUE"""),"Third Choice Group") -> Third Choice Group | AO7: =IFERROR(__xludf.DUMMYFUNCTION("""COMPUTED_VALUE"""),"Satisfactory") -> Satisfactory | AP7: =IFERROR(__xludf.DUMMYFUNCTION("""COMPUTED_VALUE"""),"Satisfactory") -> Satisfactory | AQ7: =IFERROR(__xludf.DUMMYFUNCTION("""COMPUTED_VALUE"""),"Satisfactory") -> Satisfactory | AR7: =IFERROR(__xludf.DUMMYFUNCTION("""COMPUTED_VALUE"""),"Satisfactory") -> Satisfactory | AS7: =IFERROR(__xludf.DUMMYFUNCTION("""COMPUTED_VALUE"""),"Satisfactory") -> Satisfactory | AT7: =IFERROR(__xludf.DUMMYFUNCTION("""COMPUTED_VALUE"""),"Strong") -> Strong | AU7: =IFERROR(__xludf.DUMMYFUNCTION("""COMPUTED_VALUE"""),"Unsatisfactory") -> Unsatisfactory | AV7: =IFERROR(__xludf.DUMMYFUNCTION("""COMPUTED_VALUE"""),"Satisfactory") -> Satisfactory | AW7: =IFERROR(__xludf.DUMMYFUNCTION("""COMPUTED_VALUE"""),"Monday & Wednesday: 11:00 AM–12:15 PM (CS 2075), 2:00 PM–3:20 PM, 4:30 PM–5:45 PM (BIOST 2041) Thursday: 2:30 PM–3:45 PM (BIOST 2041 Recitation) Friday: 11:00 AM–11:50 AM (CS 2075 Recitation)") -> Monday & Wednesday: 11:00 AM–12:15 PM (CS 2075), 2:00 PM–3:20 PM, 4:30 PM–5:45 PM (BIOST 2041) Thursday: 2:30 PM–3:45 PM (BIOST 2041 Recitation) Friday: 11:00 AM–11:50 AM (CS 2075 Recitation) | AX7: =IFERROR(__xludf.DUMMYFUNCTION("""COMPUTED_VALUE"""),"CS 2075") -> CS 2075 | AY7: =IFERROR(__xludf.DUMMYFUNCTION("""COMPUTED_VALUE"""),"Funding, Teaching experience, Improve public speaking or other skills, Learn a new topic") -> Funding, Teaching experience, Improve public speaking or other skills, Learn a new topic | AZ7: =IFERROR(__xludf.DUMMYFUNCTION("""COMPUTED_VALUE"""),"no") -> no
